<?xml version="1.0" ?>
<!-- =================================================================================== -->
<!-- |    This document was autogenerated by xacro from robot.urdf.xacro               | -->
<!-- |    EDITING THIS FILE BY HAND IS NOT RECOMMENDED                                 | -->
<!-- =================================================================================== -->
<robot name="j100-0001">
  <material name="clearpath_dark_grey">
    <color rgba="0.2 0.2 0.2 1.0"/>
  </material>
  <material name="clearpath_medium_grey">
    <color rgba="0.6 0.6 0.6 1.0"/>
  </material>
  <material name="clearpath_light_grey">
    <color rgba="0.8 0.8 0.8 1.0"/>
  </material>
  <material name="clearpath_yellow">
    <color rgba="0.8 0.8 0.0 1.0"/>
  </material>
  <material name="clearpath_black">
    <color rgba="0.15 0.15 0.15 1.0"/>
  </material>
  <material name="clearpath_white">
    <color rgba="1.0 1.0 1.0 1.0"/>
  </material>
  <material name="clearpath_red">
    <color rgba="1.0 0.0 0.0 1.0"/>
  </material>
  <material name="clearpath_aluminum">
    <color rgba="0.5 0.5 0.5 1"/>
  </material>
  <material name="clearpath_plastic">
    <color rgba="0.1 0.1 0.1   1"/>
  </material>
  <link name="front_left_wheel_link">
    <visual>
      <origin rpy="1.5707963267948966 0 0" xyz="0 0 0"/>
      <geometry>
        <mesh filename="package://clearpath_platform_description/meshes/j100/j100_wheel.stl"/>
      </geometry>
      <material name="clearpath_black"/>
    </visual>
    <collision>
      <origin rpy="1.5707963267948966 0 0" xyz="0 0 0"/>
      <geometry>
        <cylinder length="0.04" radius="0.098"/>
      </geometry>
    </collision>
    <inertial>
      <origin rpy="0 0 0" xyz="0 0 0"/>
      <mass value="0.477"/>
      <inertia ixx="0.0013" ixy="0" ixz="0" iyy="0.0024" iyz="0" izz="0.0013"/>
    </inertial>
  </link>
  <gazebo reference="front_left_wheel_link">
    <material>Gazebo/DarkGrey</material>
    <selfCollide>false</selfCollide>
    <mu1 value="0.5"/>
    <mu2 value="0.5"/>
    <fdir1 value="1 0 0"/>
  </gazebo>
  <joint name="front_left_wheel_joint" type="continuous">
    <parent link="chassis_link"/>
    <child link="front_left_wheel_link"/>
    <origin rpy="0 0 0" xyz="0.131 0.187795 0.0345"/>
    <axis xyz="0 1 0"/>
  </joint>
  <link name="front_right_wheel_link">
    <visual>
      <origin rpy="1.5707963267948966 0 0" xyz="0 0 0"/>
      <geometry>
        <mesh filename="package://clearpath_platform_description/meshes/j100/j100_wheel.stl"/>
      </geometry>
      <material name="clearpath_black"/>
    </visual>
    <collision>
      <origin rpy="1.5707963267948966 0 0" xyz="0 0 0"/>
      <geometry>
        <cylinder length="0.04" radius="0.098"/>
      </geometry>
    </collision>
    <inertial>
      <origin rpy="0 0 0" xyz="0 0 0"/>
      <mass value="0.477"/>
      <inertia ixx="0.0013" ixy="0" ixz="0" iyy="0.0024" iyz="0" izz="0.0013"/>
    </inertial>
  </link>
  <gazebo reference="front_right_wheel_link">
    <material>Gazebo/DarkGrey</material>
    <selfCollide>false</selfCollide>
    <mu1 value="0.5"/>
    <mu2 value="0.5"/>
    <fdir1 value="1 0 0"/>
  </gazebo>
  <joint name="front_right_wheel_joint" type="continuous">
    <parent link="chassis_link"/>
    <child link="front_right_wheel_link"/>
    <origin rpy="0 0 0" xyz="0.131 -0.187795 0.0345"/>
    <axis xyz="0 1 0"/>
  </joint>
  <link name="rear_left_wheel_link">
    <visual>
      <origin rpy="1.5707963267948966 0 0" xyz="0 0 0"/>
      <geometry>
        <mesh filename="package://clearpath_platform_description/meshes/j100/j100_wheel.stl"/>
      </geometry>
      <material name="clearpath_black"/>
    </visual>
    <collision>
      <origin rpy="1.5707963267948966 0 0" xyz="0 0 0"/>
      <geometry>
        <cylinder length="0.04" radius="0.098"/>
      </geometry>
    </collision>
    <inertial>
      <origin rpy="0 0 0" xyz="0 0 0"/>
      <mass value="0.477"/>
      <inertia ixx="0.0013" ixy="0" ixz="0" iyy="0.0024" iyz="0" izz="0.0013"/>
    </inertial>
  </link>
  <gazebo reference="rear_left_wheel_link">
    <material>Gazebo/DarkGrey</material>
    <selfCollide>false</selfCollide>
    <mu1 value="0.5"/>
    <mu2 value="0.5"/>
    <fdir1 value="1 0 0"/>
  </gazebo>
  <joint name="rear_left_wheel_joint" type="continuous">
    <parent link="chassis_link"/>
    <child link="rear_left_wheel_link"/>
    <origin rpy="0 0 0" xyz="-0.131 0.187795 0.0345"/>
    <axis xyz="0 1 0"/>
  </joint>
  <link name="rear_right_wheel_link">
    <visual>
      <origin rpy="1.5707963267948966 0 0" xyz="0 0 0"/>
      <geometry>
        <mesh filename="package://clearpath_platform_description/meshes/j100/j100_wheel.stl"/>
      </geometry>
      <material name="clearpath_black"/>
    </visual>
    <collision>
      <origin rpy="1.5707963267948966 0 0" xyz="0 0 0"/>
      <geometry>
        <cylinder length="0.04" radius="0.098"/>
      </geometry>
    </collision>
    <inertial>
      <origin rpy="0 0 0" xyz="0 0 0"/>
      <mass value="0.477"/>
      <inertia ixx="0.0013" ixy="0" ixz="0" iyy="0.0024" iyz="0" izz="0.0013"/>
    </inertial>
  </link>
  <gazebo reference="rear_right_wheel_link">
    <material>Gazebo/DarkGrey</material>
    <selfCollide>false</selfCollide>
    <mu1 value="0.5"/>
    <mu2 value="0.5"/>
    <fdir1 value="1 0 0"/>
  </gazebo>
  <joint name="rear_right_wheel_joint" type="continuous">
    <parent link="chassis_link"/>
    <child link="rear_right_wheel_link"/>
    <origin rpy="0 0 0" xyz="-0.131 -0.187795 0.0345"/>
    <axis xyz="0 1 0"/>
  </joint>
  <gazebo>
    <plugin filename="libignition-gazebo-wheel-slip-system.so" name="ignition::gazebo::systems::WheelSlip">
      <wheel link_name="front_left_wheel_link">
        <slip_compliance_lateral>1.0</slip_compliance_lateral>
        <slip_compliance_longitudinal>1.0</slip_compliance_longitudinal>
        <wheel_normal_force>40</wheel_normal_force>
        <wheel_radius>0.098</wheel_radius>
      </wheel>
      <wheel link_name="front_right_wheel_link">
        <slip_compliance_lateral>1.0</slip_compliance_lateral>
        <slip_compliance_longitudinal>1.0</slip_compliance_longitudinal>
        <wheel_normal_force>40</wheel_normal_force>
        <wheel_radius>0.098</wheel_radius>
      </wheel>
      <wheel link_name="rear_left_wheel_link">
        <slip_compliance_lateral>1.0</slip_compliance_lateral>
        <slip_compliance_longitudinal>1.0</slip_compliance_longitudinal>
        <wheel_normal_force>40</wheel_normal_force>
        <wheel_radius>0.098</wheel_radius>
      </wheel>
      <wheel link_name="rear_right_wheel_link">
        <slip_compliance_lateral>1.0</slip_compliance_lateral>
        <slip_compliance_longitudinal>1.0</slip_compliance_longitudinal>
        <wheel_normal_force>40</wheel_normal_force>
        <wheel_radius>0.098</wheel_radius>
      </wheel>
    </plugin>
  </gazebo>
  <link name="base_link"/>
  <joint name="base_link_joint" type="fixed">
    <origin rpy="0 0 0" xyz="0 0 0"/>
    <parent link="base_link"/>
    <child link="chassis_link"/>
  </joint>
  <link name="chassis_link">
    <visual>
      <origin rpy="1.5707963267948966 0 1.5707963267948966" xyz="0 0 -0.0655"/>
      <geometry>
        <mesh filename="package://clearpath_platform_description/meshes/j100/j100_base.stl"/>
      </geometry>
      <material name="clearpath_dark_grey"/>
    </visual>
    <collision>
      <origin xyz="0 0 0.092"/>
      <geometry>
        <box size="0.42 0.31 0.184"/>
      </geometry>
    </collision>
    <inertial>
      <origin rpy="0 0 0" xyz="0.012  0.002 0.067"/>
      <mass value="16.523"/>
      <inertia ixx="0.3136" ixy="-0.0008" ixz="0.0164" iyy="0.3922" iyz="-0.0009" izz="0.4485"/>
    </inertial>
  </link>
  <link name="imu_0_link">
    <inertial>
      <mass value="0.001"/>
      <origin rpy="0 0 0" xyz="0 0 0"/>
      <inertia ixx="1e-09" ixy="0.0" ixz="0.0" iyy="1e-09" iyz="0.0" izz="1e-09"/>
    </inertial>
  </link>
  <joint name="imu_joint" type="fixed">
    <parent link="chassis_link"/>
    <child link="imu_0_link"/>
  </joint>
  <gazebo reference="imu_0_link">
    <sensor name="imu_0" type="imu">
      <always_on>true</always_on>
      <update_rate>50</update_rate>
      <visualize>true</visualize>
      <ignition_frame_id>imu_0_link</ignition_frame_id>
      <topic>/sensors/imu_0/data_raw</topic>
    </sensor>
  </gazebo>
  <link name="gps_0_link">
    <visual>
      <geometry>
        <cylinder length="0.016" radius="0.026"/>
      </geometry>
      <origin xyz="0 0 0.008"/>
      <material name="clearpath_black"/>
    </visual>
  </link>
  <joint name="navsat_joint" type="fixed">
    <parent link="chassis_link"/>
    <child link="gps_0_link"/>
    <origin xyz="-0.180 0.126 0.1815"/>
  </joint>
  <gazebo reference="gps_0_link">
    <sensor name="gps_0" type="navsat">
      <always_on>1</always_on>
      <update_rate>10</update_rate>
      <ignition_frame_id>gps_0_link</ignition_frame_id>
      <topic>/sensors/gps_0/navsat</topic>
    </sensor>
  </gazebo>
  <link name="default_mount"/>
  <joint name="default_mount_joint" type="fixed">
    <parent link="chassis_link"/>
    <child link="default_mount"/>
    <origin xyz="0 0 0.184"/>
  </joint>
  <link name="rear_0_mount"/>
  <joint name="rear_0_mount_joint" type="fixed">
    <parent link="default_mount"/>
    <child link="rear_0_mount"/>
    <origin xyz="-0.12 0 0"/>
  </joint>
  <link name="front_0_mount"/>
  <joint name="front_0_mount_joint" type="fixed">
    <parent link="default_mount"/>
    <child link="front_0_mount"/>
    <origin xyz="0.12 0 0"/>
  </joint>
  <ros2_control name="j100_hardware" type="system">
    <hardware>
      <plugin>clearpath_platform/J100Hardware</plugin>
    </hardware>
    <joint name="front_left_wheel_joint">
      <command_interface name="velocity"/>
      <state_interface name="position"/>
      <state_interface name="velocity"/>
    </joint>
    <joint name="rear_left_wheel_joint">
      <command_interface name="velocity"/>
      <state_interface name="position"/>
      <state_interface name="velocity"/>
    </joint>
    <joint name="front_right_wheel_joint">
      <command_interface name="velocity"/>
      <state_interface name="position"/>
      <state_interface name="velocity"/>
    </joint>
    <joint name="rear_right_wheel_joint">
      <command_interface name="velocity"/>
      <state_interface name="position"/>
      <state_interface name="velocity"/>
    </joint>
  </ros2_control>
  <!-- Attachments -->
  <!-- Spawn fender link -->
  <link name="front_fender_link">
    <visual>
      <geometry>
        <mesh filename="package://clearpath_platform_description/meshes/j100/attachments/default_fender.stl"/>
      </geometry>
      <material name="clearpath_yellow"/>
    </visual>
  </link>
  <!-- Attach fender -->
  <joint name="front_fender_joint" type="fixed">
    <origin rpy="0.0 0.0 0.0" xyz="0.0 0.0 0.0"/>
    <parent link="base_link"/>
    <child link="front_fender_link"/>
  </joint>
  <!-- Spawn fender link -->
  <link name="rear_fender_link">
    <visual>
      <geometry>
        <mesh filename="package://clearpath_platform_description/meshes/j100/attachments/default_fender.stl"/>
      </geometry>
      <material name="clearpath_yellow"/>
    </visual>
  </link>
  <!-- Attach fender -->
  <joint name="rear_fender_joint" type="fixed">
    <origin rpy="0.0 0.0 3.1415" xyz="0.0 0.0 0.0"/>
    <parent link="base_link"/>
    <child link="rear_fender_link"/>
  </joint>
  <!-- Links -->
  <!-- Mounts -->
  <link name="bracket_0_link">
    <visual>
      <material name="clearpath_dark_grey"/>
      <geometry>
        <mesh filename="package://clearpath_mounts_description/meshes/pacs/bracket_horizontal.stl"/>
      </geometry>
      <origin rpy="0 0 0" xyz="0 0 0.010125"/>
    </visual>
    <collision>
      <origin rpy="0 0 0" xyz="0 0 0.0050625"/>
      <geometry>
        <box size="0.09 0.09 0.010125"/>
      </geometry>
    </collision>
  </link>
  <link name="bracket_0_mount"/>
  <joint name="bracket_0_joint" type="fixed">
    <child link="bracket_0_link"/>
    <parent link="base_link"/>
    <origin rpy="0.0 0.0 3.12" xyz="0.25 0.0 0.0"/>
  </joint>
  <joint name="bracket_0_mount_joint" type="fixed">
    <child link="bracket_0_mount"/>
    <parent link="bracket_0_link"/>
    <origin rpy="0 0 0" xyz="0 0 0.010125"/>
  </joint>
  <!-- Sensors -->
  <link name="lidar2d_0_link">
    <visual>
      <origin rpy="0 0 0" xyz="0 0 0"/>
      <geometry>
        <!-- Origin of this mesh is the base of the bracket. -->
        <mesh filename="package://clearpath_sensors_description/meshes/hokuyo_ust.stl"/>
      </geometry>
      <material name="clearpath_dark_grey"/>
    </visual>
  </link>
  <link name="lidar2d_0_laser">
    <inertial>
      <mass value="1.1"/>
      <origin xyz="0 0 0"/>
      <inertia ixx="0.00307156543804" ixy="0.0" ixz="0.0" iyy="0.0031284904152700005" iyz="0.0" izz="0.00196432421427"/>
    </inertial>
  </link>
  <joint name="lidar2d_0_joint" type="fixed">
    <origin rpy="0.0 0.0 0.0" xyz="0.0 0.0 0.0"/>
    <parent link="bracket_0_mount"/>
    <child link="lidar2d_0_link"/>
  </joint>
  <joint name="lidar2d_0_laser_joint" type="fixed">
    <!-- This offset is from the base of the bracket to the LIDAR's focal point. -->
    <origin rpy="0 0 0" xyz="0 0 0.0474"/>
    <parent link="lidar2d_0_link"/>
    <child link="lidar2d_0_laser"/>
  </joint>
  <gazebo reference="lidar2d_0_laser">
    <sensor name="lidar2d_0" type="gpu_lidar">
      <update_rate>50</update_rate>
      <visualize>true</visualize>
      <always_on>true</always_on>
      <ignition_frame_id>lidar2d_0_laser</ignition_frame_id>
      <topic>/sensors/lidar2d_0/scan</topic>
      <lidar>
        <scan>
          <horizontal>
            <samples>540</samples>
            <resolution>1</resolution>
            <min_angle>-2.356</min_angle>
            <max_angle>2.356</max_angle>
          </horizontal>
          <vertical>
            <samples>1</samples>
            <resolution>1</resolution>
            <min_angle>0</min_angle>
            <max_angle>0</max_angle>
          </vertical>
        </scan>
        <range>
          <min>0.05</min>
          <max>25.0</max>
          <resolution>0.01</resolution>
        </range>
      </lidar>
    </sensor>
  </gazebo>
  <!-- Manipulators -->
  <!-- Extras -->
</robot>
